Traceback (most recent call last):
  File "/opt/anaconda3/envs/portfolio/lib/python3.12/site-packages/jupyter_cache/executors/utils.py", line 58, in single_nb_execution
    executenb(
  File "/opt/anaconda3/envs/portfolio/lib/python3.12/site-packages/nbclient/client.py", line 1319, in execute
    return NotebookClient(nb=nb, resources=resources, km=km, **kwargs).execute()
           ^^^^^^^^^^^^^^^^^^^^^^^^^^^^^^^^^^^^^^^^^^^^^^^^^^^^^^^^^^^^^^^^^^^^^
  File "/opt/anaconda3/envs/portfolio/lib/python3.12/site-packages/jupyter_core/utils/__init__.py", line 165, in wrapped
    return loop.run_until_complete(inner)
           ^^^^^^^^^^^^^^^^^^^^^^^^^^^^^^
  File "/opt/anaconda3/envs/portfolio/lib/python3.12/asyncio/base_events.py", line 686, in run_until_complete
    return future.result()
           ^^^^^^^^^^^^^^^
  File "/opt/anaconda3/envs/portfolio/lib/python3.12/site-packages/nbclient/client.py", line 709, in async_execute
    await self.async_execute_cell(
  File "/opt/anaconda3/envs/portfolio/lib/python3.12/site-packages/nbclient/client.py", line 1062, in async_execute_cell
    await self._check_raise_for_error(cell, cell_index, exec_reply)
  File "/opt/anaconda3/envs/portfolio/lib/python3.12/site-packages/nbclient/client.py", line 918, in _check_raise_for_error
    raise CellExecutionError.from_cell_and_msg(cell, exec_reply_content)
nbclient.exceptions.CellExecutionError: An error occurred while executing the following cell:
------------------
insert_location_data(data_filename, normalized_database_filename)
insert_weather_type_data(data_filename, normalized_database_filename)
insert_season_data(data_filename, normalized_database_filename)
insert_cloud_cover_data(data_filename, normalized_database_filename)
insert_uv_index_data(data_filename, normalized_database_filename)
------------------


[0;31m---------------------------------------------------------------------------[0m
[0;31mFileNotFoundError[0m                         Traceback (most recent call last)
Cell [0;32mIn[11], line 1[0m
[0;32m----> 1[0m [43minsert_location_data[49m[43m([49m[43mdata_filename[49m[43m,[49m[43m [49m[43mnormalized_database_filename[49m[43m)[49m
[1;32m      2[0m insert_weather_type_data(data_filename, normalized_database_filename)
[1;32m      3[0m insert_season_data(data_filename, normalized_database_filename)

Cell [0;32mIn[5], line 7[0m, in [0;36minsert_location_data[0;34m(data_filename, normalized_database_filename)[0m
[1;32m      4[0m cursor [38;5;241m=[39m conn[38;5;241m.[39mcursor()
[1;32m      6[0m locations [38;5;241m=[39m [38;5;28mset[39m()
[0;32m----> 7[0m [38;5;28;01mwith[39;00m [38;5;28;43mopen[39;49m[43m([49m[43mdata_filename[49m[43m,[49m[43m [49m[38;5;124;43m'[39;49m[38;5;124;43mr[39;49m[38;5;124;43m'[39;49m[43m)[49m [38;5;28;01mas[39;00m file:
[1;32m      8[0m     header [38;5;241m=[39m [38;5;28;01mNone[39;00m
[1;32m      9[0m     [38;5;28;01mfor[39;00m line [38;5;129;01min[39;00m file:

File [0;32m~/pyenv_book/lib/python3.12/site-packages/IPython/core/interactiveshell.py:324[0m, in [0;36m_modified_open[0;34m(file, *args, **kwargs)[0m
[1;32m    317[0m [38;5;28;01mif[39;00m file [38;5;129;01min[39;00m {[38;5;241m0[39m, [38;5;241m1[39m, [38;5;241m2[39m}:
[1;32m    318[0m     [38;5;28;01mraise[39;00m [38;5;167;01mValueError[39;00m(
[1;32m    319[0m         [38;5;124mf[39m[38;5;124m"[39m[38;5;124mIPython won[39m[38;5;124m'[39m[38;5;124mt let you open fd=[39m[38;5;132;01m{[39;00mfile[38;5;132;01m}[39;00m[38;5;124m by default [39m[38;5;124m"[39m
[1;32m    320[0m         [38;5;124m"[39m[38;5;124mas it is likely to crash IPython. If you know what you are doing, [39m[38;5;124m"[39m
[1;32m    321[0m         [38;5;124m"[39m[38;5;124myou can use builtins[39m[38;5;124m'[39m[38;5;124m open.[39m[38;5;124m"[39m
[1;32m    322[0m     )
[0;32m--> 324[0m [38;5;28;01mreturn[39;00m [43mio_open[49m[43m([49m[43mfile[49m[43m,[49m[43m [49m[38;5;241;43m*[39;49m[43margs[49m[43m,[49m[43m [49m[38;5;241;43m*[39;49m[38;5;241;43m*[39;49m[43mkwargs[49m[43m)[49m

[0;31mFileNotFoundError[0m: [Errno 2] No such file or directory: 'weather_classification_data.csv'

